[2024-06-14T08:41:59.755+0000] {taskinstance.py:1103} INFO - Dependencies all met for dep_context=non-requeueable deps ti=<TaskInstance: api_to_s3_to_redshift_v3.ELT.data_extraction.upload_data_to_s3 manual__2024-06-14T08:36:51.341013+00:00 [queued]>
[2024-06-14T08:41:59.769+0000] {taskinstance.py:1103} INFO - Dependencies all met for dep_context=requeueable deps ti=<TaskInstance: api_to_s3_to_redshift_v3.ELT.data_extraction.upload_data_to_s3 manual__2024-06-14T08:36:51.341013+00:00 [queued]>
[2024-06-14T08:41:59.770+0000] {taskinstance.py:1308} INFO - Starting attempt 2 of 2
[2024-06-14T08:41:59.792+0000] {taskinstance.py:1327} INFO - Executing <Task(PythonOperator): ELT.data_extraction.upload_data_to_s3> on 2024-06-14 08:36:51.341013+00:00
[2024-06-14T08:41:59.801+0000] {standard_task_runner.py:57} INFO - Started process 1126 to run task
[2024-06-14T08:41:59.806+0000] {standard_task_runner.py:84} INFO - Running: ['***', 'tasks', 'run', 'api_to_s3_to_redshift_v3', 'ELT.data_extraction.upload_data_to_s3', 'manual__2024-06-14T08:36:51.341013+00:00', '--job-id', '252', '--raw', '--subdir', 'DAGS_FOLDER/test_redshift_real_v3.py', '--cfg-path', '/tmp/tmpzc_gla1m']
[2024-06-14T08:41:59.808+0000] {standard_task_runner.py:85} INFO - Job 252: Subtask ELT.data_extraction.upload_data_to_s3
[2024-06-14T08:41:59.887+0000] {task_command.py:410} INFO - Running <TaskInstance: api_to_s3_to_redshift_v3.ELT.data_extraction.upload_data_to_s3 manual__2024-06-14T08:36:51.341013+00:00 [running]> on host 9949536f6ac7
[2024-06-14T08:42:00.019+0000] {taskinstance.py:1547} INFO - Exporting env vars: AIRFLOW_CTX_DAG_OWNER='***' AIRFLOW_CTX_DAG_ID='api_to_s3_to_redshift_v3' AIRFLOW_CTX_TASK_ID='ELT.data_extraction.upload_data_to_s3' AIRFLOW_CTX_EXECUTION_DATE='2024-06-14T08:36:51.341013+00:00' AIRFLOW_CTX_TRY_NUMBER='2' AIRFLOW_CTX_DAG_RUN_ID='manual__2024-06-14T08:36:51.341013+00:00'
[2024-06-14T08:42:00.039+0000] {taskinstance.py:1824} ERROR - Task failed with exception
Traceback (most recent call last):
  File "/home/airflow/.local/lib/python3.7/site-packages/airflow/operators/python.py", line 181, in execute
    return_value = self.execute_callable()
  File "/home/airflow/.local/lib/python3.7/site-packages/airflow/operators/python.py", line 198, in execute_callable
    return self.python_callable(*self.op_args, **self.op_kwargs)
  File "/opt/airflow/dags/test_redshift_real_v3.py", line 70, in upload_to_s3
    raise ValueError("No CSV data found in XCom.")
ValueError: No CSV data found in XCom.
[2024-06-14T08:42:00.052+0000] {taskinstance.py:1350} INFO - Marking task as FAILED. dag_id=api_to_s3_to_redshift_v3, task_id=ELT.data_extraction.upload_data_to_s3, execution_date=20240614T083651, start_date=20240614T084159, end_date=20240614T084200
[2024-06-14T08:42:00.072+0000] {standard_task_runner.py:109} ERROR - Failed to execute job 252 for task ELT.data_extraction.upload_data_to_s3 (No CSV data found in XCom.; 1126)
[2024-06-14T08:42:00.098+0000] {local_task_job_runner.py:225} INFO - Task exited with return code 1
[2024-06-14T08:42:00.146+0000] {taskinstance.py:2653} INFO - 0 downstream tasks scheduled from follow-on schedule check
