[2024-06-14T08:33:20.777+0000] {taskinstance.py:1103} INFO - Dependencies all met for dep_context=non-requeueable deps ti=<TaskInstance: api_to_s3_to_redshift_v3.ELT.data_extraction.fetch_data_from_api manual__2024-06-14T08:33:18.738318+00:00 [queued]>
[2024-06-14T08:33:20.790+0000] {taskinstance.py:1103} INFO - Dependencies all met for dep_context=requeueable deps ti=<TaskInstance: api_to_s3_to_redshift_v3.ELT.data_extraction.fetch_data_from_api manual__2024-06-14T08:33:18.738318+00:00 [queued]>
[2024-06-14T08:33:20.790+0000] {taskinstance.py:1308} INFO - Starting attempt 1 of 2
[2024-06-14T08:33:20.811+0000] {taskinstance.py:1327} INFO - Executing <Task(PythonOperator): ELT.data_extraction.fetch_data_from_api> on 2024-06-14 08:33:18.738318+00:00
[2024-06-14T08:33:20.818+0000] {standard_task_runner.py:57} INFO - Started process 965 to run task
[2024-06-14T08:33:20.824+0000] {standard_task_runner.py:84} INFO - Running: ['***', 'tasks', 'run', 'api_to_s3_to_redshift_v3', 'ELT.data_extraction.fetch_data_from_api', 'manual__2024-06-14T08:33:18.738318+00:00', '--job-id', '249', '--raw', '--subdir', 'DAGS_FOLDER/test_redshift_real_v3.py', '--cfg-path', '/tmp/tmpss78vgqb']
[2024-06-14T08:33:20.825+0000] {standard_task_runner.py:85} INFO - Job 249: Subtask ELT.data_extraction.fetch_data_from_api
[2024-06-14T08:33:20.890+0000] {task_command.py:410} INFO - Running <TaskInstance: api_to_s3_to_redshift_v3.ELT.data_extraction.fetch_data_from_api manual__2024-06-14T08:33:18.738318+00:00 [running]> on host 9949536f6ac7
[2024-06-14T08:33:21.025+0000] {taskinstance.py:1547} INFO - Exporting env vars: AIRFLOW_CTX_DAG_OWNER='***' AIRFLOW_CTX_DAG_ID='api_to_s3_to_redshift_v3' AIRFLOW_CTX_TASK_ID='ELT.data_extraction.fetch_data_from_api' AIRFLOW_CTX_EXECUTION_DATE='2024-06-14T08:33:18.738318+00:00' AIRFLOW_CTX_TRY_NUMBER='1' AIRFLOW_CTX_DAG_RUN_ID='manual__2024-06-14T08:33:18.738318+00:00'
[2024-06-14T08:33:25.437+0000] {taskinstance.py:1824} ERROR - Task failed with exception
Traceback (most recent call last):
  File "/home/airflow/.local/lib/python3.7/site-packages/airflow/operators/python.py", line 181, in execute
    return_value = self.execute_callable()
  File "/home/airflow/.local/lib/python3.7/site-packages/airflow/operators/python.py", line 198, in execute_callable
    return self.python_callable(*self.op_args, **self.op_kwargs)
  File "/opt/airflow/dags/test_redshift_real_v3.py", line 62, in fetch_data_from_api
    context['ti'].xcom_push(key='csv_data', value=csv_data)
NameError: name 'context' is not defined
[2024-06-14T08:33:25.451+0000] {taskinstance.py:1350} INFO - Marking task as UP_FOR_RETRY. dag_id=api_to_s3_to_redshift_v3, task_id=ELT.data_extraction.fetch_data_from_api, execution_date=20240614T083318, start_date=20240614T083320, end_date=20240614T083325
[2024-06-14T08:33:25.476+0000] {standard_task_runner.py:109} ERROR - Failed to execute job 249 for task ELT.data_extraction.fetch_data_from_api (name 'context' is not defined; 965)
[2024-06-14T08:33:25.500+0000] {local_task_job_runner.py:225} INFO - Task exited with return code 1
[2024-06-14T08:33:25.565+0000] {taskinstance.py:2653} INFO - 0 downstream tasks scheduled from follow-on schedule check
