[2024-07-20T05:25:23.259+0000] {taskinstance.py:1979} INFO - Dependencies all met for dep_context=non-requeueable deps ti=<TaskInstance: crawling_dag.read_s3_and_compare_links manual__2024-07-20T05:25:15.668861+00:00 [queued]>
[2024-07-20T05:25:23.283+0000] {taskinstance.py:1979} INFO - Dependencies all met for dep_context=requeueable deps ti=<TaskInstance: crawling_dag.read_s3_and_compare_links manual__2024-07-20T05:25:15.668861+00:00 [queued]>
[2024-07-20T05:25:23.284+0000] {taskinstance.py:2193} INFO - Starting attempt 1 of 2
[2024-07-20T05:25:23.323+0000] {taskinstance.py:2217} INFO - Executing <Task(PythonOperator): read_s3_and_compare_links> on 2024-07-20 05:25:15.668861+00:00
[2024-07-20T05:25:23.336+0000] {standard_task_runner.py:60} INFO - Started process 87 to run task
[2024-07-20T05:25:23.347+0000] {standard_task_runner.py:87} INFO - Running: ['***', 'tasks', 'run', 'crawling_dag', 'read_s3_and_compare_links', 'manual__2024-07-20T05:25:15.668861+00:00', '--job-id', '472', '--raw', '--subdir', 'DAGS_FOLDER/musinsa_dag.py', '--cfg-path', '/tmp/tmpply3vurj']
[2024-07-20T05:25:23.357+0000] {standard_task_runner.py:88} INFO - Job 472: Subtask read_s3_and_compare_links
[2024-07-20T05:25:23.567+0000] {task_command.py:423} INFO - Running <TaskInstance: crawling_dag.read_s3_and_compare_links manual__2024-07-20T05:25:15.668861+00:00 [running]> on host 23922dccf21d
[2024-07-20T05:25:23.855+0000] {taskinstance.py:2513} INFO - Exporting env vars: AIRFLOW_CTX_DAG_OWNER='***' AIRFLOW_CTX_DAG_ID='crawling_dag' AIRFLOW_CTX_TASK_ID='read_s3_and_compare_links' AIRFLOW_CTX_EXECUTION_DATE='2024-07-20T05:25:15.668861+00:00' AIRFLOW_CTX_TRY_NUMBER='1' AIRFLOW_CTX_DAG_RUN_ID='manual__2024-07-20T05:25:15.668861+00:00'
[2024-07-20T05:25:23.890+0000] {base.py:83} INFO - Using connection ID 'aws_s3' for task execution.
[2024-07-20T05:25:23.892+0000] {connection_wrapper.py:384} INFO - AWS Connection (conn_id='aws_s3', conn_type='aws') credentials retrieved from login and password.
[2024-07-20T05:26:21.992+0000] {logging_mixin.py:188} INFO - Current number of unique href links: 43
[2024-07-20T05:26:49.445+0000] {logging_mixin.py:188} INFO - Current number of unique href links: 86
[2024-07-20T05:26:53.985+0000] {taskinstance.py:2731} ERROR - Task failed with exception
Traceback (most recent call last):
  File "/home/airflow/.local/lib/python3.8/site-packages/airflow/models/taskinstance.py", line 444, in _execute_task
    result = _execute_callable(context=context, **execute_callable_kwargs)
  File "/home/airflow/.local/lib/python3.8/site-packages/airflow/models/taskinstance.py", line 414, in _execute_callable
    return execute_callable(context=context, **execute_callable_kwargs)
  File "/home/airflow/.local/lib/python3.8/site-packages/airflow/operators/python.py", line 200, in execute
    return_value = self.execute_callable()
  File "/home/airflow/.local/lib/python3.8/site-packages/airflow/operators/python.py", line 217, in execute_callable
    return self.python_callable(*self.op_args, **self.op_kwargs)
  File "/opt/airflow/dags/code_test/airflow_product_review.py", line 208, in read_s3_and_compare_links
    href_links = get_href_links(driver, wait, actions, num_items_to_fetch=100)
  File "/opt/airflow/dags/code_test/airflow_product_review.py", line 27, in get_href_links
    href = element.get_attribute('href')
  File "/home/airflow/.local/lib/python3.8/site-packages/selenium/webdriver/remote/webelement.py", line 178, in get_attribute
    attribute_value = self.parent.execute_script(
  File "/home/airflow/.local/lib/python3.8/site-packages/selenium/webdriver/remote/webdriver.py", line 414, in execute_script
    return self.execute(command, {"script": script, "args": converted_args})["value"]
  File "/home/airflow/.local/lib/python3.8/site-packages/selenium/webdriver/remote/webdriver.py", line 354, in execute
    self.error_handler.check_response(response)
  File "/home/airflow/.local/lib/python3.8/site-packages/selenium/webdriver/remote/errorhandler.py", line 229, in check_response
    raise exception_class(message, screen, stacktrace)
selenium.common.exceptions.StaleElementReferenceException: Message: stale element reference: stale element not found in the current frame
  (Session info: chrome-headless-shell=126.0.6478.114); For documentation on this error, please visit: https://www.selenium.dev/documentation/webdriver/troubleshooting/errors#stale-element-reference-exception
Stacktrace:
#0 0x55bda9cb669a <unknown>
#1 0x55bda99990dc <unknown>
#2 0x55bda999e7e9 <unknown>
#3 0x55bda99a085c <unknown>
#4 0x55bda9a285a9 <unknown>
#5 0x55bda9a08872 <unknown>
#6 0x55bda9a275c3 <unknown>
#7 0x55bda9a08613 <unknown>
#8 0x55bda99d84f7 <unknown>
#9 0x55bda99d8e4e <unknown>
#10 0x55bda9c7c86b <unknown>
#11 0x55bda9c80911 <unknown>
#12 0x55bda9c6835e <unknown>
#13 0x55bda9c81472 <unknown>
#14 0x55bda9c4ccbf <unknown>
#15 0x55bda9ca6098 <unknown>
#16 0x55bda9ca6270 <unknown>
#17 0x55bda9cb57cc <unknown>
#18 0x7fc0bc8f0ac3 <unknown>

[2024-07-20T05:26:54.079+0000] {taskinstance.py:1149} INFO - Marking task as UP_FOR_RETRY. dag_id=crawling_dag, task_id=read_s3_and_compare_links, execution_date=20240720T052515, start_date=20240720T052523, end_date=20240720T052654
[2024-07-20T05:26:54.335+0000] {standard_task_runner.py:107} ERROR - Failed to execute job 472 for task read_s3_and_compare_links (Message: stale element reference: stale element not found in the current frame
  (Session info: chrome-headless-shell=126.0.6478.114); For documentation on this error, please visit: https://www.selenium.dev/documentation/webdriver/troubleshooting/errors#stale-element-reference-exception
Stacktrace:
#0 0x55bda9cb669a <unknown>
#1 0x55bda99990dc <unknown>
#2 0x55bda999e7e9 <unknown>
#3 0x55bda99a085c <unknown>
#4 0x55bda9a285a9 <unknown>
#5 0x55bda9a08872 <unknown>
#6 0x55bda9a275c3 <unknown>
#7 0x55bda9a08613 <unknown>
#8 0x55bda99d84f7 <unknown>
#9 0x55bda99d8e4e <unknown>
#10 0x55bda9c7c86b <unknown>
#11 0x55bda9c80911 <unknown>
#12 0x55bda9c6835e <unknown>
#13 0x55bda9c81472 <unknown>
#14 0x55bda9c4ccbf <unknown>
#15 0x55bda9ca6098 <unknown>
#16 0x55bda9ca6270 <unknown>
#17 0x55bda9cb57cc <unknown>
#18 0x7fc0bc8f0ac3 <unknown>
; 87)
[2024-07-20T05:26:54.403+0000] {local_task_job_runner.py:234} INFO - Task exited with return code 1
[2024-07-20T05:26:54.561+0000] {taskinstance.py:3312} INFO - 0 downstream tasks scheduled from follow-on schedule check
